Workbook

Sheet Resumo
A1: Espaço Wellness do Esporte Clube Sírio: resumo do orçamento
A2: Valores em R$. Preços consultados em 29/10/2026. Cada linha das abas de cenário diz se o preço é Real (página do vendedor), Real (busca), Referência (SINAPI, tabela oficial) ou Estimativa.
A4: Grupo | B4: Essencial | C4: Recomendado | D4: Premium
A5: Banheiras de gelo | B5: =Essencial!G7 -> 129360 | C5: =Recomendado!G7 -> 204036 | D5: =Premium!G7 -> 548800
A6: Sauna seca finlandesa | B6: =Essencial!G11 -> 122465.5 | C6: =Recomendado!G11 -> 181171.1 | D6: =Premium!G11 -> 296700
A7: Sauna a vapor | B7: =Essencial!G16 -> 81799.3 | C7: =Recomendado!G16 -> 118376.24 | D7: =Premium!G15 -> 241200
A8: Sauna infravermelha | B8: 0 | C8: =Recomendado!G20 -> 72499 | D8: =Premium!G19 -> 125300
A9: Duchas de experiência e aquecimento de água | B9: =Essencial!G23 -> 22057.55 | C9: =Recomendado!G29 -> 65961.16 | D9: =Premium!G28 -> 106990.05
A10: Armários, bebedouro e lounge | B10: =Essencial!G30 -> 52568.59 | C10: =Recomendado!G36 -> 111770.77 | D10: =Premium!G35 -> 201040.41
A11: Pergolado e painel de privacidade | B11: =Essencial!G34 -> 92794 | C11: =Recomendado!G40 -> 162000 | D11: =Premium!G40 -> 296497
A12: Piso, impermeabilização e drenagem | B12: =Essencial!G42 -> 55313.15 | C12: =Recomendado!G51 -> 116458.02 | D12: =Premium!G51 -> 116458.02
A13: Infraestrutura e instalação | B13: =Essencial!G49 -> 212000 | C13: =Recomendado!G58 -> 240000 | D13: =Premium!G58 -> 298000
A14: Reforço estrutural (reserva) | B14: =Essencial!G52 -> 60000 | C14: =Recomendado!G61 -> 80000 | D14: =Premium!G61 -> 100000
A15: Segurança, iluminação, som e acesso | B15: =Essencial!G55 -> 8000 | C15: =Recomendado!G67 -> 58000 | D15: =Premium!G67 -> 97000
A16: Projeto, laudos e aprovações | B16: =Essencial!G64 -> 104631.08 | C16: =Recomendado!G76 -> 153631.08 | D16: =Premium!G76 -> 201631.08
A17: Subtotal | B17: =Essencial!G66 -> 940989.17 | C17: =Recomendado!G78 -> 1563903.4 | D17: =Premium!G78 -> 2629616.6
A18: BDI e administração da obra (15% sobre obra civil) | B18: =Essencial!G69 -> 64216.073 | C18: =Recomendado!G81 -> 98468.703 | D18: =Premium!G81 -> 136193.25
A19: Contingência (12%) | B19: =Essencial!G71 -> 120624.63 | C19: =Recomendado!G83 -> 199484.65 | D19: =Premium!G83 -> 331897.18
A20: TOTAL | B20: =Essencial!G72 -> 1125829.9 | C20: =Recomendado!G84 -> 1861856.7 | D20: =Premium!G84 -> 3097707
A21: Teto do clube | B21: 2000000
A22: Folga em relação ao teto (negativo = acima) | B22: =$B$21-B20 -> 874170.13 | C22: =$B$21-C20 -> 138143.28 | D22: =$B$21-D20 -> -1097707
A23: Custo por sócio (5000 sócios), investimento | B23: =B20/5000 -> 225.16597 | C23: =C20/5000 -> 372.37134 | D23: =D20/5000 -> 619.5414

Sheet Essencial
A1: Orçamento detalhado, cenário Essencial
A2: Equipamentos nacionais, sem sauna infravermelha, lounge com o deck existente. Preços consultados em 29/10/2026. Azul = valor digitado (entrada); preto = fórmula.
A4: Grupo | B4: Item | C4: Fornecedor | D4: Qtd | E4: Un | F4: Unitário (R$) | G4: Total (R$) | H4: Tipo | I4: Base / observação | J4: Link | K4: Data da consulta
A5: Banheiras de gelo | B5: Banheira de gelo Ice Flow Uno Intense, 290 L, 4 °C, ozônio e filtro, para 30+ usuários/dia | C5: Pretty Jet / Ice Flow | D5: 4 | E5: un | F5: 29840 | G5: =D5*F5 -> 119360 | H5: Real | I5: Preço PIX | J5: https://iceflow.com.br/precos | K5: 29/10/2026
A6: Banheiras de gelo | B6: Frete, nivelamento da base e ligação elétrica dedicada das banheiras | C6: Instalador | D6: 4 | E6: un | F6: 2500 | G6: =D6*F6 -> 10000 | H6: Estimativa | I6: Valor de mercado para instalação simples; incerteza média | K6: 29/10/2026
A7: Subtotal Banheiras de gelo | G7: =SUM(G5:G6) -> 129360
A9: Sauna seca finlandesa | B9: Sala de sauna seca sob medida, 12 lugares (4,5 x 3,0 m), lambril de cedrinho, bancos em 2 níveis, porta de vidro, isolamento | C9: Marcenaria de saunas | D9: 1 | E9: vb | F9: 115000 | G9: =D9*F9 -> 115000 | H9: Estimativa | I9: Ancorada na Móveis Deck (R$ 12.559/m² de projeção); faixa de R$ 120 mil a R$ 250 mil com aquecedor; incerteza média a alta | J9: https://www.moveisdeck.com.br/produtos/sauna-deck-completa-seca/ | K9: 29/10/2026
A10: Sauna seca finlandesa | B10: Aquecedor elétrico 18 kW com quadro digital (até 55,5 m³) | C10: Globaltech Brasil (Impercap) | D10: 1 | E10: un | F10: 7465.5 | G10: =D10*F10 -> 7465.5 | H10: Real | I10: Preço PIX/boleto | J10: https://www.globaltechbrasil.com/saunas/sauna-seca-eletrica-quadro-comando-digital-18kw-impercap-ate-55-5m | K10: 29/10/2026
A11: Subtotal Sauna seca finlandesa | G11: =SUM(G9:G10) -> 122465.5
A13: Sauna a vapor | B13: Sala de vapor em alvenaria com pastilha, bancos e teto inclinado, 8 lugares (3,0 x 2,5 m) | C13: Construtora | D13: 1 | E13: vb | F13: 75000 | G13: =D13*F13 -> 75000 | H13: Estimativa | I13: 45 m² de pastilha (SINAPI 88789, R$ 433/m²) + impermeabilização, bancos, teto e instalações; incerteza média | J13: https://orcamentor.com/composicao/88789/ | K13: 29/10/2026
A14: Sauna a vapor | B14: Gerador de vapor Compact Line Inox 24 kW (até 40 m³) | C14: Globaltech Brasil (Sodramar) | D14: 1 | E14: un | F14: 4108.5 | G14: =D14*F14 -> 4108.5 | H14: Real | I14: Preço PIX | J14: https://www.globaltechbrasil.com/saunas/sauna-a-vapor-compact-line-inox-24kw-sodramar-para-ate-40m | K14: 29/10/2026
A15: Sauna a vapor | B15: Porta de aço inox 0,57 x 1,90 m com visor | C15: Sol e Água (Sodramar) | D15: 1 | E15: un | F15: 2690.8 | G15: =D15*F15 -> 2690.8 | H15: Real (busca) | I15: Visto em busca; confirmar | J15: https://www.google.com/search?q=porta+de+vidro+temperado+para+sauna+a+vapor+OR+seca+pre%C3%A7o+Sodramar&hl=pt-BR&gl=br | K15: 29/10/2026
A16: Subtotal Sauna a vapor | G16: =SUM(G13:G15) -> 81799.3
A18: Duchas de experiência e aquecimento de água | B18: Balde de água fria basculante em inox, sob medida | C18: Serralheria inox | D18: 1 | E18: un | F18: 5000 | G18: =D18*F18 -> 5000 | H18: Estimativa | I18: Não há produto nacional de catálogo; faixa de R$ 3 mil a R$ 8 mil; incerteza alta | K18: 29/10/2026
A19: Duchas de experiência e aquecimento de água | B19: Misturador termostático para chuveiro de contraste (Decaterm 2430) | C19: Amazon (Deca) | D19: 1 | E19: un | F19: 4750 | G19: =D19*F19 -> 4750 | H19: Real (busca) | I19: Visto em busca; confirmar | J19: https://www.google.com/search?q=misturador+termost%C3%A1tico+chuveiro+parede+pre%C3%A7o+Deca+OR+Docol+OR+Hansgrohe&hl=pt-BR&gl=br | K19: 29/10/2026
A20: Duchas de experiência e aquecimento de água | B20: Ducha cascata linear inox 304, 60 cm | C20: Cascatas & Cia | D20: 1 | E20: un | F20: 1009.17 | G20: =D20*F20 -> 1009.17 | H20: Real | I20: Preço PIX | J20: https://www.cascatasecia.com.br/produto/cascata-ducha-linear-em-inox-304-para-ambientes-externos-60cm-zgmmaiv6/ | K20: 29/10/2026
A21: Duchas de experiência e aquecimento de água | B21: Ducha coluna tubular inox 316 (higienização e ducha acessível) | C21: Cascatas & Cia | D21: 2 | E21: un | F21: 3003.49 | G21: =D21*F21 -> 6006.98 | H21: Real | I21: Preço PIX | J21: https://www.cascatasecia.com.br/produto/ducha-piscina-coluna-tubular-em-inox-316-c-001-cascatas-cia-i0glbe9o/ | K21: 29/10/2026
A22: Duchas de experiência e aquecimento de água | B22: Aquecedor a gás de passagem Rinnai REU E35, 35 L/min | C22: Multi Aquecedores | D22: 1 | E22: un | F22: 5291.4 | G22: =D22*F22 -> 5291.4 | H22: Real | I22: Preço PIX; depende de ponto de gás no local | J22: https://loja.multiaquecedores.com.br/aquecedor-a-gas-rinnai-reu-e35-fea-35-litros-gn-ou-glp | K22: 29/10/2026
A23: Subtotal Duchas de experiência e aquecimento de água | G23: =SUM(G18:G22) -> 22057.55
A25: Armários, bebedouro e lounge | B25: Armários fenólicos TS 10 mm para área úmida, instalados | C25: Fabricante de divisórias TS | D25: 30 | E25: porta | F25: 1200 | G25: =D25*F25 -> 36000 | H25: Estimativa | I25: Chapa TS a cerca de R$ 600/m² + ferragens inox e montagem; faixa R$ 900 a R$ 1.800; incerteza alta | J25: https://www.google.com/search?q=divis%C3%B3ria+sanit%C3%A1ria+fen%C3%B3lica+TS+10mm+pre%C3%A7o+m2&hl=pt-BR&gl=br | K25: 29/10/2026
A26: Armários, bebedouro e lounge | B26: Bebedouro industrial inox 50 L, água gelada (Libell LIC050) | C26: Dutra Máquinas | D26: 1 | E26: un | F26: 1619.91 | G26: =D26*F26 -> 1619.91 | H26: Real (busca) | I26: Visto em busca; confirmar | J26: https://www.google.com/search?q=bebedouro+industrial+inox+50+litros+%C3%A1gua+gelada+pre%C3%A7o+IBBL+OR+Libell+OR+Venax&hl=pt-BR&gl=br | K26: 29/10/2026
A27: Armários, bebedouro e lounge | B27: Espreguiçadeira Tramontina Leblon (kit com 6) | C27: Loja do Mecânico | D27: 2 | E27: kit | F27: 1519.92 | G27: =D27*F27 -> 3039.84 | H27: Real (busca) | I27: Visto em busca; confirmar | J27: https://www.lojadomecanico.com.br/produto/74017/59/513/espreguicadeira-leblon-branca-tramontina-92256010 | K27: 29/10/2026
A28: Armários, bebedouro e lounge | B28: Sofá externo 3 lugares, alumínio e corda náutica (Arte Mobiliário Vip) | C28: Arte Mobiliário | D28: 2 | E28: un | F28: 2954.42 | G28: =D28*F28 -> 5908.84 | H28: Real (busca) | I28: Visto em busca; frete à parte | J28: https://www.google.com/search?q=sof%C3%A1+%C3%A1rea+externa+alum%C3%ADnio+corda+n%C3%A1utica+3+lugares+estofado+imperme%C3%A1vel+pre%C3%A7o&hl=pt-BR&gl=br | K28: 29/10/2026
A29: Armários, bebedouro e lounge | B29: Toalheiros, lixeiras, relógios de parede e comunicação visual | C29: Diversos | D29: 1 | E29: vb | F29: 6000 | G29: =D29*F29 -> 6000 | H29: Estimativa | I29: Verba | K29: 29/10/2026
A30: Subtotal Armários, bebedouro e lounge | G30: =SUM(G25:G29) -> 52568.59
A32: Pergolado e painel de privacidade | B32: Pergolado de madeira sobre as banheiras | C32: SINAPI 103315 | D32: 40 | E32: m² | F32: 319.85 | G32: =D32*F32 -> 12794 | H32: Referência | I32: Composição SINAPI 09/2026, média nacional | J32: https://orcamentor.com/composicao/103315/ | K32: 29/10/2026
A33: Pergolado e painel de privacidade | B33: Painel de privacidade ripado em madeira tratada, 2,2 m de altura, instalado | C33: Serralheria e marcenaria | D33: 100 | E33: m² | F33: 800 | G33: =D33*F33 -> 80000 | H33: Estimativa | I33: Faixa de R$ 700 a R$ 1.500/m² instalado; incerteza média | J33: https://www.ripatto.com.br | K33: 29/10/2026
A34: Subtotal Pergolado e painel de privacidade | G34: =SUM(G32:G33) -> 92794
A36: Piso, impermeabilização e drenagem | B36: Demolição do deck na zona molhada e descarte | C36: Construtora | D36: 110 | E36: m² | F36: 60 | G36: =D36*F36 -> 6600 | H36: Estimativa | I36: Mão de obra e caçamba; incerteza média | K36: 29/10/2026
A37: Piso, impermeabilização e drenagem | B37: Regularização com caimento de 1% a 2% para os ralos | C37: Construtora | D37: 110 | E37: m² | F37: 90 | G37: =D37*F37 -> 9900 | H37: Estimativa | I37: Contrapiso armado; incerteza média | K37: 29/10/2026
A38: Piso, impermeabilização e drenagem | B38: Impermeabilização com manta asfáltica 4 mm | C38: SINAPI 98546 | D38: 110 | E38: m² | F38: 137.79 | G38: =D38*F38 -> 15156.9 | H38: Referência | I38: Composição SINAPI 09/2026 | J38: https://orcamentor.com/composicao/98546/ | K38: 29/10/2026
A39: Piso, impermeabilização e drenagem | B39: Proteção mecânica 3 cm | C39: SINAPI 98565 | D39: 110 | E39: m² | F39: 65.7 | G39: =D39*F39 -> 7227 | H39: Referência | I39: Composição SINAPI 09/2026 | J39: https://orcamentor.com/composicao/98565/ | K39: 29/10/2026
A40: Piso, impermeabilização e drenagem | B40: Porcelanato externo antiderrapante 60 x 60 assentado (exigir R11) | C40: SINAPI 87263 | D40: 110 | E40: m² | F40: 113.68 | G40: =D40*F40 -> 12504.8 | H40: Referência | I40: Composição SINAPI 09/2026 com material e mão de obra | J40: https://orcamentor.com/composicao/87263/ | K40: 29/10/2026
A41: Piso, impermeabilização e drenagem | B41: Ralo linear inox 100 cm | C41: Leroy Merlin | D41: 15 | E41: un | F41: 261.63 | G41: =D41*F41 -> 3924.45 | H41: Real (busca) | I41: Visto em busca; confirmar | J41: https://www.google.com/search?q=ralo+linear+inox+100+cm+%C3%A1rea+externa+pre%C3%A7o&hl=pt-BR&gl=br | K41: 29/10/2026
A42: Subtotal Piso, impermeabilização e drenagem | G42: =SUM(G36:G41) -> 55313.15
A44: Infraestrutura e instalação | B44: Elétrica: ramal trifásico dedicado (60 a 90 kW), quadro com DR, aterramento equipotencial e iluminação de serviço | C44: Instaladora elétrica | D44: 1 | E44: vb | F44: 85000 | G44: =D44*F44 -> 85000 | H44: Estimativa | I44: Horas SINAPI de eletricista (R$ 45,13/h) + cabos e quadros; depende da distância ao quadro geral; incerteza alta | J44: https://orcamentor.com/composicao/88264/ | K44: 29/10/2026
A45: Infraestrutura e instalação | B45: Hidráulica: água fria e quente, esgoto, pluvial e ligação das banheiras | C45: Instaladora hidráulica | D45: 1 | E45: vb | F45: 55000 | G45: =D45*F45 -> 55000 | H45: Estimativa | I45: Horas SINAPI de encanador (R$ 40,92/h) + tubulações; incerteza alta | J45: https://orcamentor.com/composicao/88267/ | K45: 29/10/2026
A46: Infraestrutura e instalação | B46: Exaustão e ventilação das saunas | C46: Instaladora | D46: 1 | E46: vb | F46: 12000 | G46: =D46*F46 -> 12000 | H46: Estimativa | I46: Dutos, grelhas e exaustor temporizado | K46: 29/10/2026
A47: Infraestrutura e instalação | B47: Casa de máquinas compacta e ventilada | C47: Construtora | D47: 1 | E47: vb | F47: 20000 | G47: =D47*F47 -> 20000 | H47: Estimativa | I47: Abrigo para quadros, aquecedor e gerador | K47: 29/10/2026
A48: Infraestrutura e instalação | B48: Montagem e comissionamento dos equipamentos | C48: Fornecedores e instaladora | D48: 1 | E48: vb | F48: 40000 | G48: =D48*F48 -> 40000 | H48: Estimativa | I48: 10% a 20% do valor dos equipamentos nacionais | K48: 29/10/2026
...

Sheet Recomendado
A1: Orçamento detalhado, cenário Recomendado
A2: Sauna seca para 16, infravermelho, banheiras de 2 pessoas com vidro, iluminação cênica e controle de acesso. Preços consultados em 29/10/2026. Azul = valor digitado (entrada); preto = fórmula.
A4: Grupo | B4: Item | C4: Fornecedor | D4: Qtd | E4: Un | F4: Unitário (R$) | G4: Total (R$) | H4: Tipo | I4: Base / observação | J4: Link | K4: Data da consulta
A5: Banheiras de gelo | B5: Banheira de gelo Ice Flow Glass para 2 pessoas, 195 x 90 cm, lateral de vidro, 4 °C | C5: Pretty Jet / Ice Flow | D5: 4 | E5: un | F5: 48009 | G5: =D5*F5 -> 192036 | H5: Real | I5: Preço PIX | J5: https://iceflow.com.br/precos | K5: 29/10/2026
A6: Banheiras de gelo | B6: Frete, nivelamento da base e ligação elétrica dedicada das banheiras | C6: Instalador | D6: 4 | E6: un | F6: 3000 | G6: =D6*F6 -> 12000 | H6: Estimativa | I6: Valor de mercado; incerteza média | K6: 29/10/2026
A7: Subtotal Banheiras de gelo | G7: =SUM(G5:G6) -> 204036
A9: Sauna seca finlandesa | B9: Sala de sauna seca sob medida, 16 lugares, bancos em 3 níveis, janela panorâmica, iluminação LED quente | C9: Marcenaria de saunas | D9: 1 | E9: vb | F9: 165000 | G9: =D9*F9 -> 165000 | H9: Estimativa | I9: Ancorada na Móveis Deck; faixa de R$ 120 mil a R$ 250 mil; incerteza média a alta | J9: https://www.moveisdeck.com.br/produtos/sauna-deck-completa-seca/ | K9: 29/10/2026
A10: Sauna seca finlandesa | B10: Aquecedor elétrico 27 kW com comando Wi-Fi | C10: Piscinacenter (Impercap) | D10: 1 | E10: un | F10: 16171.1 | G10: =D10*F10 -> 16171.1 | H10: Real (busca) | I10: Visto em busca, à vista; confirmar | J10: https://www.google.com/search?q=sauna+seca+finlandesa+montada+pre%C3%A7o+por+m2+madeira+cedro&hl=pt-BR&gl=br | K10: 29/10/2026
A11: Subtotal Sauna seca finlandesa | G11: =SUM(G9:G10) -> 181171.1
A13: Sauna a vapor | B13: Sala de vapor com pastilha de porcelana, bancos ergonômicos e teto inclinado, 8 lugares | C13: Construtora | D13: 1 | E13: vb | F13: 110000 | G13: =D13*F13 -> 110000 | H13: Estimativa | I13: Faixa de R$ 70 mil a R$ 150 mil; incerteza média | J13: https://orcamentor.com/composicao/88789/ | K13: 29/10/2026
A14: Sauna a vapor | B14: Gerador de vapor 24 kW inox com comando digital | C14: Globaltech Brasil (Impercap) | D14: 1 | E14: un | F14: 5685.44 | G14: =D14*F14 -> 5685.44 | H14: Real | I14: Preço PIX | J14: https://www.globaltechbrasil.com/saunas/sauna-vapor-eletrica-24kw-inox-comando-digital-impercap | K14: 29/10/2026
A15: Sauna a vapor | B15: Porta de aço inox 0,57 x 1,90 m com visor | C15: Sol e Água (Sodramar) | D15: 1 | E15: un | F15: 2690.8 | G15: =D15*F15 -> 2690.8 | H15: Real (busca) | I15: Visto em busca; confirmar | J15: https://www.google.com/search?q=porta+de+vidro+temperado+para+sauna+a+vapor+OR+seca+pre%C3%A7o+Sodramar&hl=pt-BR&gl=br | K15: 29/10/2026
A16: Subtotal Sauna a vapor | G16: =SUM(G13:G15) -> 118376.24
A18: Sauna infravermelha | B18: Sauna infravermelha Kiva Radiance full spectrum, 4 pessoas | C18: Kiva Wellness Brasil | D18: 1 | E18: un | F18: 57499 | G18: =D18*F18 -> 57499 | H18: Real | I18: Preço cheio; garantia comercial de 1 ano | J18: https://kivawellness.com.br/products/sauna-4-pessoas-infravermelho-full-spectrum | K18: 29/10/2026
A19: Sauna infravermelha | B19: Abrigo fechado e ventilado para a cabine infravermelha | C19: Marcenaria | D19: 1 | E19: vb | F19: 15000 | G19: =D19*F19 -> 15000 | H19: Estimativa | I19: Cabine é de uso interno e precisa de abrigo ao ar livre | K19: 29/10/2026
A20: Subtotal Sauna infravermelha | G20: =SUM(G18:G19) -> 72499
A22: Duchas de experiência e aquecimento de água | B22: Balde de água fria TylöHelo (importado, internado) | C22: esaunashop (UE) | D22: 1 | E22: un | F22: 13600 | G22: =D22*F22 -> 13600 | H22: Estimativa sobre preço real | I22: € 1.075 + frete + impostos (fator de cerca de 2,1) | J22: https://esaunashop.com/tylohelo-cold-shower-bucket | K22: 29/10/2026
A23: Duchas de experiência e aquecimento de água | B23: Misturador termostático para chuveiros de contraste (Decaterm 2430) | C23: Amazon (Deca) | D23: 2 | E23: un | F23: 4750 | G23: =D23*F23 -> 9500 | H23: Real (busca) | I23: Visto em busca; confirmar | J23: https://www.google.com/search?q=misturador+termost%C3%A1tico+chuveiro+parede+pre%C3%A7o+Deca+OR+Docol+OR+Hansgrohe&hl=pt-BR&gl=br | K23: 29/10/2026
A24: Duchas de experiência e aquecimento de água | B24: Ducha cascata linear inox 304, 100 cm | C24: Cascatas & Cia | D24: 1 | E24: un | F24: 1345.58 | G24: =D24*F24 -> 1345.58 | H24: Real | I24: Preço PIX | J24: https://www.cascatasecia.com.br/produto/cascata-ducha-linear-em-inox-304-para-ambientes-externos-100cm-28v9y5ft/ | K24: 29/10/2026
A25: Duchas de experiência e aquecimento de água | B25: Cascata chuva inox 316 de embutir com LED | C25: Tropical Cascatas | D25: 1 | E25: un | F25: 1826.2 | G25: =D25*F25 -> 1826.2 | H25: Real | I25: Preço à vista | J25: https://tropicalcascatas.com.br/produto/cascata-chuva-inox-de-embutir-led/ | K25: 29/10/2026
A26: Duchas de experiência e aquecimento de água | B26: Ducha coluna tubular inox 316 (higienização e ducha acessível) | C26: Cascatas & Cia | D26: 2 | E26: un | F26: 3003.49 | G26: =D26*F26 -> 6006.98 | H26: Real | I26: Preço PIX | J26: https://www.cascatasecia.com.br/produto/ducha-piscina-coluna-tubular-em-inox-316-c-001-cascatas-cia-i0glbe9o/ | K26: 29/10/2026
A27: Duchas de experiência e aquecimento de água | B27: Bomba de calor para banho Fromtherm FH40, água a 60 °C | C27: Globaltech Brasil | D27: 1 | E27: un | F27: 23682.4 | G27: =D27*F27 -> 23682.4 | H27: Real | I27: Preço à vista | J27: https://www.globaltechbrasil.com/5067-bomba-de-calor-para-banho-fromtherm-fh40-60 | K27: 29/10/2026
A28: Duchas de experiência e aquecimento de água | B28: Reservatório térmico 500 L | C28: Diversos | D28: 1 | E28: un | F28: 10000 | G28: =D28*F28 -> 10000 | H28: Estimativa | I28: Sem preço público; faixa de R$ 6 mil a R$ 15 mil | K28: 29/10/2026
A29: Subtotal Duchas de experiência e aquecimento de água | G29: =SUM(G22:G28) -> 65961.16
A31: Armários, bebedouro e lounge | B31: Armários fenólicos TS 10 mm com fechadura eletrônica, instalados | C31: Fabricante de divisórias TS | D31: 40 | E31: porta | F31: 1400 | G31: =D31*F31 -> 56000 | H31: Estimativa | I31: Faixa R$ 900 a R$ 1.800 por porta; incerteza alta | J31: https://www.google.com/search?q=divis%C3%B3ria+sanit%C3%A1ria+fen%C3%B3lica+TS+10mm+pre%C3%A7o+m2&hl=pt-BR&gl=br | K31: 29/10/2026
A32: Armários, bebedouro e lounge | B32: Bebedouro industrial inox 50 L com filtro (Venâncio BI50L) | C32: Extra | D32: 1 | E32: un | F32: 2732.41 | G32: =D32*F32 -> 2732.41 | H32: Real (busca) | I32: Visto em busca; confirmar | J32: https://www.extra.com.br/kit-bebedouro-industrial-50-litros-refrigerado-inox-bi50l-220v-filtro-venancio/p/1579422979 | K32: 29/10/2026
A33: Armários, bebedouro e lounge | B33: Espreguiçadeira de alumínio e corda náutica (Kiev) | C33: Leroy Merlin | D33: 8 | E33: un | F33: 1980 | G33: =D33*F33 -> 15840 | H33: Real (busca) | I33: Visto em busca; confirmar | J33: https://www.google.com/search?q=espregui%C3%A7adeira+alum%C3%ADnio+piscina+fibra+sint%C3%A9tica+OR+corda+n%C3%A1utica+pre%C3%A7o&hl=pt-BR&gl=br | K33: 29/10/2026
A34: Armários, bebedouro e lounge | B34: Sofá externo 3 lugares com espuma para área externa (Sulvimes Acapulco) | C34: Sulvimes | D34: 3 | E34: un | F34: 9066.12 | G34: =D34*F34 -> 27198.36 | H34: Real (busca) | I34: Visto em busca; confirmar | J34: https://www.google.com/search?q=sof%C3%A1+%C3%A1rea+externa+alum%C3%ADnio+corda+n%C3%A1utica+3+lugares+estofado+imperme%C3%A1vel+pre%C3%A7o&hl=pt-BR&gl=br | K34: 29/10/2026
A35: Armários, bebedouro e lounge | B35: Toalheiros, lixeiras, chá e água, paisagismo e comunicação visual | C35: Diversos | D35: 1 | E35: vb | F35: 10000 | G35: =D35*F35 -> 10000 | H35: Estimativa | I35: Verba | K35: 29/10/2026
A36: Subtotal Armários, bebedouro e lounge | G36: =SUM(G31:G35) -> 111770.77
A38: Pergolado e painel de privacidade | B38: Pergolado de alumínio com policarbonato alveolar sobre banheiras e duchas | C38: Serralheria | D38: 70 | E38: m² | F38: 900 | G38: =D38*F38 -> 63000 | H38: Estimativa | I38: Guias de mercado: R$ 680 a R$ 1.100/m² | J38: https://www.google.com/search?q=pergolado+alum%C3%ADnio+pre%C3%A7o+m2+instalado+2026&hl=pt-BR&gl=br | K38: 29/10/2026
A39: Pergolado e painel de privacidade | B39: Painel de privacidade ripado de alumínio, 2,2 m de altura, instalado | C39: Ripatto e serralheria | D39: 110 | E39: m² | F39: 900 | G39: =D39*F39 -> 99000 | H39: Estimativa | I39: Material R$ 575/m² (real, busca) + estrutura e montagem | J39: https://www.ripatto.com.br | K39: 29/10/2026
A40: Subtotal Pergolado e painel de privacidade | G40: =SUM(G38:G39) -> 162000
A42: Piso, impermeabilização e drenagem | B42: Demolição do deck na zona molhada e descarte | C42: Construtora | D42: 130 | E42: m² | F42: 60 | G42: =D42*F42 -> 7800 | H42: Estimativa | I42: Incerteza média | K42: 29/10/2026
A43: Piso, impermeabilização e drenagem | B43: Regularização com caimento de 1% a 2% para os ralos | C43: Construtora | D43: 130 | E43: m² | F43: 90 | G43: =D43*F43 -> 11700 | H43: Estimativa | I43: Incerteza média | K43: 29/10/2026
A44: Piso, impermeabilização e drenagem | B44: Impermeabilização com manta asfáltica 4 mm | C44: SINAPI 98546 | D44: 130 | E44: m² | F44: 137.79 | G44: =D44*F44 -> 17912.7 | H44: Referência | I44: Composição SINAPI 09/2026 | J44: https://orcamentor.com/composicao/98546/ | K44: 29/10/2026
A45: Piso, impermeabilização e drenagem | B45: Proteção mecânica 3 cm | C45: SINAPI 98565 | D45: 130 | E45: m² | F45: 65.7 | G45: =D45*F45 -> 8541 | H45: Referência | I45: Composição SINAPI 09/2026 | J45: https://orcamentor.com/composicao/98565/ | K45: 29/10/2026
A46: Piso, impermeabilização e drenagem | B46: Porcelanato externo Portobello Oasi Duna 90 x 90 (exigir R11), com 10% de perda | C46: Telhanorte | D46: 143 | E46: m² | F46: 174.9 | G46: =D46*F46 -> 25010.7 | H46: Real | I46: Preço da página | J46: https://www.telhanorte.com.br/porcelanato-oasi-duna-90x90-ext-ret-cx-2-42-m2-portobello-2547929/p | K46: 29/10/2026
A47: Piso, impermeabilização e drenagem | B47: Assentamento do porcelanato (mão de obra e argamassa) | C47: Construtora | D47: 130 | E47: m² | F47: 60 | G47: =D47*F47 -> 7800 | H47: Estimativa | I47: Incerteza média | K47: 29/10/2026
A48: Piso, impermeabilização e drenagem | B48: Ralo linear inox Royal 100 cm | C48: Ralo Linear | D48: 18 | E48: un | F48: 740.74 | G48: =D48*F48 -> 13333.32 | H48: Real (busca) | I48: Visto em busca; confirmar | J48: https://www.ralolinear.com.br | K48: 29/10/2026
...

Sheet Premium
A1: Orçamento detalhado, cenário Premium
A2: Banheiras e aquecedores importados, pérgolas bioclimáticas e acabamentos em pedra. Passa do teto. Preços consultados em 29/10/2026. Azul = valor digitado (entrada); preto = fórmula.
A4: Grupo | B4: Item | C4: Fornecedor | D4: Qtd | E4: Un | F4: Unitário (R$) | G4: Total (R$) | H4: Tipo | I4: Base / observação | J4: Link | K4: Data da consulta
A5: Banheiras de gelo | B5: Banheira de gelo Plunge All-In Commercial, filtro NSF50, ozônio (importada, internada) | C5: Plunge (EUA) | D5: 4 | E5: un | F5: 133200 | G5: =D5*F5 -> 532800 | H5: Estimativa sobre preço real | I5: US$ 12.990 + frete US$ 1.500 + impostos e despesas | J5: https://business.plunge.com/products/plunge-all-in-commercial | K5: 29/10/2026
A6: Banheiras de gelo | B6: Frete interno, base e ligação elétrica dedicada das banheiras | C6: Instalador | D6: 4 | E6: un | F6: 4000 | G6: =D6*F6 -> 16000 | H6: Estimativa | I6: Incerteza média | K6: 29/10/2026
A7: Subtotal Banheiras de gelo | G7: =SUM(G5:G6) -> 548800
A9: Sauna seca finlandesa | B9: Sala de sauna seca premium sob projeto, 16 lugares, madeira termotratada e vidro panorâmico | C9: Fabricante sob orçamento | D9: 1 | E9: vb | F9: 220000 | G9: =D9*F9 -> 220000 | H9: Estimativa | I9: Sem preço público; incerteza alta | J9: https://www.moveisdeck.com.br/produtos/sauna-deck-completa-seca/ | K9: 29/10/2026
A10: Sauna seca finlandesa | B10: Aquecedor Harvia Virta Pro 20 kW com comando Xenio e pedras (importado, internado) | C10: Topture (EUA) | D10: 1 | E10: un | F10: 76700 | G10: =D10*F10 -> 76700 | H10: Estimativa sobre preço real | I10: Kit US$ 7.207 + frete + impostos | J10: https://topture.com/products/harvia-virta-pro-series-sauna-heater-20kw | K10: 29/10/2026
A11: Subtotal Sauna seca finlandesa | G11: =SUM(G9:G10) -> 296700
A13: Sauna a vapor | B13: Sala de vapor premium com pedra natural, bancos aquecidos e teto abobadado | C13: Construtora | D13: 1 | E13: vb | F13: 160000 | G13: =D13*F13 -> 160000 | H13: Estimativa | I13: Faixa de R$ 150 mil a R$ 250 mil no premium; incerteza alta | J13: https://orcamentor.com/composicao/88789/ | K13: 29/10/2026
A14: Sauna a vapor | B14: Gerador Tylö Steam Commercial 15 kW com comando Elite (importado, internado) | C14: Pool and Spa Centre (UK) | D14: 1 | E14: un | F14: 81200 | G14: =D14*F14 -> 81200 | H14: Estimativa sobre preço real | I14: £ 5.636 + frete + impostos | J14: https://www.poolandspacentre.co.uk/tylo-steam-commercial-generator.html | K14: 29/10/2026
A15: Subtotal Sauna a vapor | G15: =SUM(G13:G14) -> 241200
A17: Sauna infravermelha | B17: Sauna infravermelha Clearlight Sanctuary Retreat full spectrum, 3 a 4 pessoas (importada, internada) | C17: Clearlight (loja oficial, EUA) | D17: 1 | E17: un | F17: 105300 | G17: =D17*F17 -> 105300 | H17: Estimativa sobre preço real | I17: US$ 9.499 (basswood) + frete US$ 1.500 + impostos e 6% de despesas | J17: https://healwithheat.com/sanctuary-retreat/ | K17: 29/10/2026
A18: Sauna infravermelha | B18: Abrigo fechado e ventilado para a cabine infravermelha | C18: Marcenaria | D18: 1 | E18: vb | F18: 20000 | G18: =D18*F18 -> 20000 | H18: Estimativa | I18: Verba | K18: 29/10/2026
A19: Subtotal Sauna infravermelha | G19: =SUM(G17:G18) -> 125300
A21: Duchas de experiência e aquecimento de água | B21: Balde de água fria TylöHelo (importado, internado) | C21: esaunashop (UE) | D21: 2 | E21: un | F21: 13600 | G21: =D21*F21 -> 27200 | H21: Estimativa sobre preço real | I21: € 1.075 + frete + impostos | J21: https://esaunashop.com/tylohelo-cold-shower-bucket | K21: 29/10/2026
A22: Duchas de experiência e aquecimento de água | B22: Misturador termostático para chuveiros de contraste (Decaterm 2430) | C22: Amazon (Deca) | D22: 3 | E22: un | F22: 4750 | G22: =D22*F22 -> 14250 | H22: Real (busca) | I22: Visto em busca; confirmar | J22: https://www.google.com/search?q=misturador+termost%C3%A1tico+chuveiro+parede+pre%C3%A7o+Deca+OR+Docol+OR+Hansgrohe&hl=pt-BR&gl=br | K22: 29/10/2026
A23: Duchas de experiência e aquecimento de água | B23: Ducha cascata linear inox 304, 300 cm | C23: Cascatas & Cia | D23: 1 | E23: un | F23: 5046.22 | G23: =D23*F23 -> 5046.22 | H23: Real | I23: Preço PIX | J23: https://www.cascatasecia.com.br/produto/cascata-ducha-linear-em-inox-304-para-ambientes-externos-300cm-a79tdhm7/ | K23: 29/10/2026
A24: Duchas de experiência e aquecimento de água | B24: Cascata chuva inox 316 de embutir com LED | C24: Tropical Cascatas | D24: 2 | E24: un | F24: 1826.2 | G24: =D24*F24 -> 3652.4 | H24: Real | I24: Preço à vista | J24: https://tropicalcascatas.com.br/produto/cascata-chuva-inox-de-embutir-led/ | K24: 29/10/2026
A25: Duchas de experiência e aquecimento de água | B25: Ducha coluna tubular inox 316 (higienização e ducha acessível) | C25: Cascatas & Cia | D25: 2 | E25: un | F25: 3003.49 | G25: =D25*F25 -> 6006.98 | H25: Real | I25: Preço PIX | J25: https://www.cascatasecia.com.br/produto/ducha-piscina-coluna-tubular-em-inox-316-c-001-cascatas-cia-i0glbe9o/ | K25: 29/10/2026
A26: Duchas de experiência e aquecimento de água | B26: Bomba de calor para banho Fromtherm FH80, água a 60 °C | C26: Globaltech Brasil | D26: 1 | E26: un | F26: 35834.45 | G26: =D26*F26 -> 35834.45 | H26: Real | I26: Preço à vista | J26: https://www.globaltechbrasil.com/7009-bomba-de-calor-para-banho-fromtherm-fh80-60o | K26: 29/10/2026
A27: Duchas de experiência e aquecimento de água | B27: Reservatório térmico 1.000 L | C27: Diversos | D27: 1 | E27: un | F27: 15000 | G27: =D27*F27 -> 15000 | H27: Estimativa | I27: Sem preço público; incerteza alta | K27: 29/10/2026
A28: Subtotal Duchas de experiência e aquecimento de água | G28: =SUM(G21:G27) -> 106990.05
A30: Armários, bebedouro e lounge | B30: Armários em inox 304 com fechadura eletrônica, instalados | C30: Sob encomenda | D30: 40 | E30: porta | F30: 2500 | G30: =D30*F30 -> 100000 | H30: Estimativa | I30: Faixa de R$ 2 mil a R$ 4 mil por porta; incerteza alta | K30: 29/10/2026
A31: Armários, bebedouro e lounge | B31: Bebedouro industrial inox 50 L com filtro (Venâncio BI50L) | C31: Extra | D31: 1 | E31: un | F31: 2732.41 | G31: =D31*F31 -> 2732.41 | H31: Real (busca) | I31: Visto em busca; confirmar | J31: https://www.extra.com.br/kit-bebedouro-industrial-50-litros-refrigerado-inox-bi50l-220v-filtro-venancio/p/1579422979 | K31: 29/10/2026
A32: Armários, bebedouro e lounge | B32: Espreguiçadeira premium de alumínio e corda náutica (Noronha) | C32: Decor'Da Móveis | D32: 10 | E32: un | F32: 3370 | G32: =D32*F32 -> 33700 | H32: Real (busca) | I32: Visto em busca; confirmar | J32: https://www.google.com/search?q=espregui%C3%A7adeira+alum%C3%ADnio+piscina+fibra+sint%C3%A9tica+OR+corda+n%C3%A1utica+pre%C3%A7o&hl=pt-BR&gl=br | K32: 29/10/2026
A33: Armários, bebedouro e lounge | B33: Sofá externo 3 lugares alto padrão (CarmelaBlend Maldivas) | C33: CarmelaBlend | D33: 3 | E33: un | F33: 16536 | G33: =D33*F33 -> 49608 | H33: Real (busca) | I33: Visto em busca; confirmar | J33: https://www.google.com/search?q=sof%C3%A1+%C3%A1rea+externa+alum%C3%ADnio+corda+n%C3%A1utica+3+lugares+estofado+imperme%C3%A1vel+pre%C3%A7o&hl=pt-BR&gl=br | K33: 29/10/2026
A34: Armários, bebedouro e lounge | B34: Toalheiros aquecidos, chá e água, paisagismo e comunicação visual | C34: Diversos | D34: 1 | E34: vb | F34: 15000 | G34: =D34*F34 -> 15000 | H34: Estimativa | I34: Verba | K34: 29/10/2026
A35: Subtotal Armários, bebedouro e lounge | G35: =SUM(G30:G34) -> 201040.41
A37: Pergolado e painel de privacidade | B37: Pérgola bioclimática de lâminas 4 x 5 m (Pergolux) | C37: Pergolux Brasil | D37: 3 | E37: un | F37: 42499 | G37: =D37*F37 -> 127497 | H37: Real (busca) | I37: Visto em busca; montagem à parte | J37: https://www.google.com/search?q=pergolado+alum%C3%ADnio+pre%C3%A7o+m2+instalado+2026&hl=pt-BR&gl=br | K37: 29/10/2026
A38: Pergolado e painel de privacidade | B38: Montagem e fixação das pérgolas | C38: Serralheria | D38: 1 | E38: vb | F38: 15000 | G38: =D38*F38 -> 15000 | H38: Estimativa | I38: Verba | K38: 29/10/2026
A39: Pergolado e painel de privacidade | B39: Painel de privacidade em alumínio ripado com vidro jateado, instalado | C39: Serralheria | D39: 110 | E39: m² | F39: 1400 | G39: =D39*F39 -> 154000 | H39: Estimativa | I39: Faixa de R$ 700 a R$ 1.500/m² | J39: https://www.ripatto.com.br | K39: 29/10/2026
A40: Subtotal Pergolado e painel de privacidade | G40: =SUM(G37:G39) -> 296497
A42: Piso, impermeabilização e drenagem | B42: Demolição do deck na zona molhada e descarte | C42: Construtora | D42: 130 | E42: m² | F42: 60 | G42: =D42*F42 -> 7800 | H42: Estimativa | I42: Incerteza média | K42: 29/10/2026
A43: Piso, impermeabilização e drenagem | B43: Regularização com caimento de 1% a 2% para os ralos | C43: Construtora | D43: 130 | E43: m² | F43: 90 | G43: =D43*F43 -> 11700 | H43: Estimativa | I43: Incerteza média | K43: 29/10/2026
A44: Piso, impermeabilização e drenagem | B44: Impermeabilização com manta asfáltica 4 mm | C44: SINAPI 98546 | D44: 130 | E44: m² | F44: 137.79 | G44: =D44*F44 -> 17912.7 | H44: Referência | I44: Composição SINAPI 09/2026 | J44: https://orcamentor.com/composicao/98546/ | K44: 29/10/2026
A45: Piso, impermeabilização e drenagem | B45: Proteção mecânica 3 cm | C45: SINAPI 98565 | D45: 130 | E45: m² | F45: 65.7 | G45: =D45*F45 -> 8541 | H45: Referência | I45: Composição SINAPI 09/2026 | J45: https://orcamentor.com/composicao/98565/ | K45: 29/10/2026
A46: Piso, impermeabilização e drenagem | B46: Porcelanato externo Portobello Oasi Duna 90 x 90 (exigir R11), com 10% de perda | C46: Telhanorte | D46: 143 | E46: m² | F46: 174.9 | G46: =D46*F46 -> 25010.7 | H46: Real | I46: Preço da página | J46: https://www.telhanorte.com.br/porcelanato-oasi-duna-90x90-ext-ret-cx-2-42-m2-portobello-2547929/p | K46: 29/10/2026
A47: Piso, impermeabilização e drenagem | B47: Assentamento do porcelanato (mão de obra e argamassa) | C47: Construtora | D47: 130 | E47: m² | F47: 60 | G47: =D47*F47 -> 7800 | H47: Estimativa | I47: Incerteza média | K47: 29/10/2026
A48: Piso, impermeabilização e drenagem | B48: Ralo linear inox Royal 100 cm | C48: Ralo Linear | D48: 18 | E48: un | F48: 740.74 | G48: =D48*F48 -> 13333.32 | H48: Real (busca) | I48: Visto em busca; confirmar | J48: https://www.ralolinear.com.br | K48: 29/10/2026
...

Sheet Custo operacional
A1: Custo operacional mensal estimado (cenário Recomendado)
A2: Azul = premissa editável. Todos os valores são estimativas com a base indicada.
A4: Premissa | B4: Valor | C4: Base | D4: Link
A5: Tarifa de energia B3 com tributos (R$/kWh) | B5: 1.05 | C5: Enel SP, B3 R$ 0,789 sem tributos desde 04/07/2026; com ICMS e PIS/COFINS R$ 1,02 a R$ 1,08 | D5: https://calculadoraenergia.com.br/tarifa/enel-sp
A6: Água e esgoto comercial (R$/m³, acima de 50 m³) | B6: 63.68 | C6: Sabesp/ARSESP, vigência jan/2026 | D6: https://www.arsesp.sp.gov.br/Documentosgerais/NT_1__REAJUSTE_TARIFARIO_DA_SABESP__Tarifa_Aplicacao___URAE1___assinado.pdf
A7: Horas de funcionamento por dia | B7: 14 | C7: Premissa: 8 h às 22 h
A8: Visitas por dia (ocupação média de 40%) | B8: 170 | C8: Cálculo da capacidade: 30 pessoas por hora x 14 h x 40%
A9: Custo de um posto terceirizado de 44 h (R$/mês) | B9: 5500 | C9: Faixa de R$ 4.500 a R$ 6.500 com encargos | D9: https://www.al.sp.gov.br/spl/2026/05/Acessorio/1000690012_1000859822_Acessorio.pdf
A11: Energia | B11: kW | C11: Fração de uso | D11: Horas/dia | E11: kWh/mês | F11: Custo (R$/mês)
A12: Sauna seca (aquecedor) | B12: 20 | C12: 0.45 | D12: =$B$7 -> 14 | E12: =B12*C12*D12*30 -> 3780 | F12: =E12*$B$5 -> 3969
A13: Sauna a vapor (gerador) | B13: 24 | C13: 0.3 | D13: =$B$7 -> 14 | E13: =B13*C13*D13*30 -> 3024 | F13: =E13*$B$5 -> 3175.2
A14: Sauna infravermelha | B14: 2.62 | C14: 0.6 | D14: 10 | E14: =B14*C14*D14*30 -> 471.6 | F14: =E14*$B$5 -> 495.18
A15: 4 chillers das banheiras | B15: 4 | C15: 0.6 | D15: 24 | E15: =B15*C15*D15*30 -> 1728 | F15: =E15*$B$5 -> 1814.4
A16: Bomba de calor das duchas | B16: 2 | C16: 1 | D16: =$B$7 -> 14 | E16: =B16*C16*D16*30 -> 840 | F16: =E16*$B$5 -> 882
A17: Iluminação, bombas, exaustão e bebedouro | B17: 1.5 | C17: 1 | D17: =$B$7 -> 14 | E17: =B17*C17*D17*30 -> 630 | F17: =E17*$B$5 -> 661.5
A18: Total energia | E18: =SUM(E12:E17) -> 10473.6 | F18: =SUM(F12:F17) -> 10997.28
A20: Água e esgoto | B20: m³/mês | F20: Custo (R$/mês)
A21: Duchas (2 por visita, 25 L cada) | B21: 255 | F21: =B21*$B$6 -> 16238.4
A22: Troca de água das banheiras (semanal) | B22: 7 | F22: =B22*$B$6 -> 445.76
A23: Sauna a vapor | B23: 3 | F23: =B23*$B$6 -> 191.04
A24: Limpeza | B24: 10 | F24: =B24*$B$6 -> 636.8
A25: Total água e esgoto | F25: =SUM(F21:F24) -> 17512
A27: Pessoal e manutenção | B27: Postos | F27: Custo (R$/mês)
A28: Atendentes (2,5 postos para cobrir 14 h por dia, 7 dias) | B28: 2.5 | F28: =B28*$B$9 -> 13750
A29: Limpeza (1 posto) | B29: 1 | F29: =B29*$B$9 -> 5500
A30: Manutenção preventiva de saunas e chillers | C30: Faixa de R$ 800 a R$ 2.500/mês; estimativa | F30: 1650
A31: Filtros, ozônio, cloro e química das banheiras | C31: Refil de filtro R$ 80 (Ice Flow) trocado a cada 15 dias em uso comercial + química | F31: 1000
A32: Reserva para reposição (pedras, resistências, peças) | C32: Estimativa | F32: 1500
A33: Total pessoal e manutenção | F33: =SUM(F28:F32) -> 23400
A35: CUSTO OPERACIONAL MENSAL | F35: =F18+F25+F33 -> 51909.28
A36: Por sócio por mês (5000 sócios) | F36: =F35/5000 -> 10.381856
A37: Por visita | F37: =F35/($B$8*30) -> 10.17829
A39: Fora do total: lavanderia de toalhas, se o clube fornecer (cerca de R$ 2,50 por visita). Parte da água das duchas já é consumida hoje pelos sócios na piscina.

Sheet Cronograma
A1: Cronograma por fases (semanas a partir da aprovação no comitê)
A2: Semana 1 = 04/01/2027 se o comitê aprovar até dezembro de 2026. Inauguração prevista na semana 39 (fim de setembro de 2027).
A4: Fase | B4: Início (semana) | C4: Duração (semanas) | D4: Fim (semana) | E4: 1 | F4: 2 | G4: 3 | H4: 4 | I4: 5 | J4: 6 | K4: 7 | L4: 8 | M4: 9 | N4: 10 | O4: 11 | P4: 12 | Q4: 13 | R4: 14 | S4: 15 | T4: 16 | U4: 17 | V4: 18 | W4: 19 | X4: 20 | Y4: 21 | Z4: 22 | AA4: 23 | AB4: 24 | AC4: 25 | AD4: 26 | AE4: 27 | AF4: 28 | AG4: 29 | AH4: 30 | AI4: 31 | AJ4: 32 | AK4: 33 | AL4: 34 | AM4: 35 | AN4: 36 | AO4: 37 | AP4: 38 | AQ4: 39 | AR4: 40
A5: Levantamento e laudo estrutural | B5: 1 | C5: 3 | D5: =B5+C5-1 -> 3
A6: Projeto executivo e complementares | B6: 3 | C6: 8 | D6: =B6+C6-1 -> 10
A7: Aprovações: Prefeitura, Bombeiros e Vigilância Sanitária | B7: 9 | C7: 12 | D7: =B7+C7-1 -> 20
A8: Compra e fabricação dos equipamentos nacionais | B8: 14 | C8: 9 | D8: =B8+C8-1 -> 22
A9: Importados, só no Premium (60 a 120 dias) | B9: 11 | C9: 18 | D9: =B9+C9-1 -> 28
A10: Demolição do deck e preparo | B10: 20 | C10: 2 | D10: =B10+C10-1 -> 21
A11: Reforço estrutural, se o laudo pedir | B11: 22 | C11: 3 | D11: =B11+C11-1 -> 24
A12: Infraestrutura hidráulica e elétrica | B12: 23 | C12: 6 | D12: =B12+C12-1 -> 28
A13: Impermeabilização e teste de estanqueidade | B13: 27 | C13: 4 | D13: =B13+C13-1 -> 30
A14: Piso, pergolado e painéis de privacidade | B14: 30 | C14: 5 | D14: =B14+C14-1 -> 34
A15: Instalação das saunas, banheiras e duchas | B15: 31 | C15: 5 | D15: =B15+C15-1 -> 35
A16: Acabamentos, mobiliário e paisagismo | B16: 34 | C16: 3 | D16: =B16+C16-1 -> 36
... A18: Inauguração | B18: 39 | C18: 1 | D18: =B18+C18-1 -> 39

Sheet Fontes
A1: Fontes e tipos de preço
A3: Tipo | B3: Significado
A4: Real | B4: Preço público lido na página do vendedor em 29/10/2026.
A5: Real (busca) | B5: Preço visto no Google Shopping ou em resultado de busca; a página do vendedor bloqueia leitura automática. Confirmar antes de comprar.
A6: Referência | B6: Tabela oficial ou índice: SINAPI 09/2026, CUB SindusCon-SP set/2026, tarifas, taxas, PTAX.
A7: Estimativa | B7: Sem preço público. Base e incerteza descritas na linha.
A8: Estimativa sobre preço real | B8: Importado: preço real de origem + frete + II, IPI, PIS/COFINS e ICMS-SP + 6% de despesas. PTAX 29/10/2026: US$ 1 = R$ 5,3744; € 1 = R$ 6,00; £ 1 = R$ 7,1899.
A9: CUB R8-N set/2026 | B9: R$ 2.238,58/m² sem desoneração (SindusCon-SP), usado como referência de custo de obra.
A11: Links usados
A12: https://business.plunge.com/products/plunge-all-in-commercial
A13: https://deckdeck.com.br/produto/deck-ecologico-in-brasil-tipo-ype-02-pecas-32x150x3000-090-m2-a-caixa/
A14: https://engefogo.com.br/avcb-e-clcb/quanto-custa
A15: https://esaunashop.com/tylohelo-cold-shower-bucket
A16: https://gelohealth.com.br/collections/all
A17: https://healwithheat.com/sanctuary-retreat/
A18: https://iceflow.com.br/precos
A19: https://kivawellness.com.br/products/sauna-4-pessoas-infravermelho-full-spectrum
A20: https://larpontual.com.br/portal/o-que-faz-um-engenheiro-civil
A21: https://loja.multiaquecedores.com.br/aquecedor-a-gas-rinnai-reu-e35-fea-35-litros-gn-ou-glp
A22: https://orcamentor.com/composicao/103315/
... A61: https://www.telhanorte.com.br/porcelanato-oasi-duna-90x90-ext-ret-cx-2-42-m2-portobello-2547929/p
